<?xml version="1.0"?>
<robot name="doteacher_car" xmlns:xacro="http://ros.org/wiki/xacro">

    <!-- Define robot constants -->
    <xacro:property name="base_width" value="0.125" />
    <xacro:property name="base_length" value="0.29" />
    <xacro:property name="base_height" value="0.21" />

    <xacro:property name="base_collision_width" value="0.082" />
    <xacro:property name="base_collision_length" value="0.29" />
    <xacro:property name="base_collision_height" value="0.21" />

    <xacro:property name="wheel_radius" value="0.0325" />
    <xacro:property name="wheel_width" value="0.027" />
    <xacro:property name="wheel_ygap" value="0.02" />

    <xacro:property name="wheel_zoff" value="0.02" />
    <xacro:property name="wheel_drive_xoff" value="0.102" />
    <xacro:property name="wheel_steer_xoff" value="0.035" />

    <!-- Define intertial property macros  -->
    <xacro:macro name="box_inertia" params="m w h d">
        <inertial>
            <origin xyz="0 0 0" rpy="${pi/2} 0 ${pi/2}" />
            <mass value="${m}" />
            <inertia ixx="${(m/12) * (h*h + d*d)}" ixy="0.0" ixz="0.0" iyy="${(m/12) * (w*w + d*d)}"
                iyz="0.0" izz="${(m/12) * (w*w + h*h)}" />
        </inertial>
    </xacro:macro>

    <xacro:macro name="cylinder_inertia" params="m r h">
        <inertial>
            <origin xyz="0 0 0" rpy="${pi/2} 0 0" />
            <mass value="${m}" />
            <inertia ixx="${(m/12) * (3*r*r + h*h)}" ixy="0" ixz="0" iyy="${(m/12) * (3*r*r + h*h)}"
                iyz="0" izz="${(m/2) * (r*r)}" />
        </inertial>
    </xacro:macro>

    <xacro:macro name="sphere_inertia" params="m r">
        <inertial>
            <mass value="${m}" />
            <inertia ixx="${(2/5) * m * (r*r)}" ixy="0.0" ixz="0.0" iyy="${(2/5) * m * (r*r)}"
                iyz="0.0" izz="${(2/5) * m * (r*r)}" />
        </inertial>
    </xacro:macro>

    <!-- Robot Base -->
    <link name="base_link">
        <visual>
            <geometry>
                <box size="${base_length} ${base_width} ${base_height}" />
            </geometry>
            <material name="Cyan">
                <color rgba="0 1.0 1.0 1.0" />
            </material>
        </visual>

        <collision>
            <geometry>
                <box size="${base_collision_length} ${base_collision_width} ${base_height}" />
            </geometry>
        </collision>

        <xacro:box_inertia m="15" w="${base_collision_width}" d="${base_collision_length}"
            h="${base_collision_height}" />
    </link>

    <!-- Robot Footprint -->
    <link name="base_footprint" />

    <joint name="base_joint" type="fixed">
        <parent link="base_link" />
        <child link="base_footprint" />
        <origin xyz="0.0 0.0 ${-(base_height/2+wheel_radius-wheel_zoff)}" rpy="0 0 0" />
    </joint>

    <!-- Drive Wheels -->
    <xacro:macro name="wheel_drive" params="prefix x_reflect y_reflect">
        <link name="${prefix}_link">
            <visual>
                <origin xyz="0 0 0" rpy="${pi/2} 0 0" />
                <geometry>
                    <cylinder radius="${wheel_radius}" length="${wheel_width}" />
                </geometry>
                <material name="Gray">
                    <color rgba="0.5 0.5 0.5 1.0" />
                </material>
            </visual>

            <collision>
                <origin xyz="0 0 0" rpy="${pi/2} 0 0" />
                <geometry>
                    <cylinder radius="${wheel_radius}" length="${wheel_width}" />
                </geometry>
            </collision>

            <xacro:cylinder_inertia m="0.5" r="${wheel_radius}" h="${wheel_width}" />
        </link>

        <joint name="${prefix}_joint" type="continuous">
            <parent link="base_link" />
            <child link="${prefix}_link" />
            <origin
                xyz="${x_reflect*wheel_drive_xoff} ${y_reflect*(base_collision_width/2+wheel_ygap)} ${-(base_collision_height/2-wheel_zoff)}"
                rpy="0 0 0" />
            <axis xyz="0 1 0" />
        </joint>
    </xacro:macro>

    <!-- Steer Wheels -->
    <xacro:macro name="wheel_steer" params="prefix x_reflect y_reflect">
        <link name="${prefix}_link">
            <visual>
                <origin xyz="0 0 0" rpy="${pi/2} 0 0" />
                <geometry>
                    <cylinder radius="${wheel_radius}" length="${wheel_width}" />
                </geometry>
                <material name="Gray">
                    <color rgba="0.5 0.5 0.5 1.0" />
                </material>
            </visual>

            <collision>
                <origin xyz="0 0 0" rpy="${pi/2} 0 0" />
                <geometry>
                    <cylinder radius="${wheel_radius}" length="${wheel_width}" />
                </geometry>
            </collision>

            <xacro:cylinder_inertia m="0.5" r="${wheel_radius}" h="${wheel_width}" />
        </link>

        <joint name="${prefix}_joint" type="continuous">
            <parent link="base_link" />
            <child link="${prefix}_link" />
            <origin
                xyz="${x_reflect*wheel_steer_xoff} ${y_reflect*(base_collision_width/2+wheel_ygap)} ${-(base_collision_height/2-wheel_zoff)}"
                rpy="0 0 0" />
            <axis xyz="0 1 0" />
        </joint>
    </xacro:macro>

    <xacro:wheel_drive prefix="drivewhl_l" x_reflect="-1" y_reflect="1" />
    <xacro:wheel_drive prefix="drivewhl_r" x_reflect="-1" y_reflect="-1" />

    <xacro:wheel_steer prefix="steerwhl_l" x_reflect="1" y_reflect="1" />
    <xacro:wheel_steer prefix="steerwhl_r" x_reflect="1" y_reflect="-1" />
</robot>